2023-01-25 15:39:08,688 - instabot version: 0.117.0 (bot) - INFO - Instabot version: 0.117.0 Started
2023-01-25 15:39:08,689 - instabot version: 0.117.0 (bot) - DEBUG - Bot imported from C:\Users\Rajesh\AppData\Roaming\Python\Python311\site-packages\instabot\bot\bot.py
2023-01-25 15:39:08,690 - instabot version: 0.117.0 (api_login) - INFO - Not yet logged in starting: PRE-LOGIN FLOW!
2023-01-25 15:39:08,700 - instabot version: 0.117.0 (api) - WARNING - HTTPSConnectionPool(host='i.instagram.com', port=443): Max retries exceeded with url: /api/v1/accounts/get_prefill_candidates/ (Caused by NewConnectionError('<urllib3.connection.HTTPSConnection object at 0x000002598CB0E950>: Failed to establish a new connection: [Errno 11001] getaddrinfo failed'))
2023-01-25 15:39:08,705 - instabot version: 0.117.0 (api) - WARNING - HTTPSConnectionPool(host='i.instagram.com', port=443): Max retries exceeded with url: /api/v1/qe/sync/ (Caused by NewConnectionError('<urllib3.connection.HTTPSConnection object at 0x000002598CB0F390>: Failed to establish a new connection: [Errno 11001] getaddrinfo failed'))
2023-01-25 15:39:08,709 - instabot version: 0.117.0 (api) - WARNING - HTTPSConnectionPool(host='i.instagram.com', port=443): Max retries exceeded with url: /api/v1/launcher/sync/ (Caused by NewConnectionError('<urllib3.connection.HTTPSConnection object at 0x000002598CB0FA90>: Failed to establish a new connection: [Errno 11001] getaddrinfo failed'))
2023-01-25 15:39:08,713 - instabot version: 0.117.0 (api) - WARNING - HTTPSConnectionPool(host='i.instagram.com', port=443): Max retries exceeded with url: /api/v1/accounts/contact_point_prefill/ (Caused by NewConnectionError('<urllib3.connection.HTTPSConnection object at 0x000002598CB10150>: Failed to establish a new connection: [Errno 11001] getaddrinfo failed'))
