2023-01-29 09:23:32,691 - instabot version: 0.117.0 (bot) - INFO - Instabot version: 0.117.0 Started
2023-01-29 09:23:32,691 - instabot version: 0.117.0 (bot) - DEBUG - Bot imported from C:\Users\Rajesh\AppData\Roaming\Python\Python311\site-packages\instabot\bot\bot.py
2023-01-29 09:23:32,691 - instabot version: 0.117.0 (api_login) - INFO - Not yet logged in starting: PRE-LOGIN FLOW!
2023-01-29 09:23:32,706 - instabot version: 0.117.0 (api) - WARNING - HTTPSConnectionPool(host='i.instagram.com', port=443): Max retries exceeded with url: /api/v1/accounts/get_prefill_candidates/ (Caused by NewConnectionError('<urllib3.connection.HTTPSConnection object at 0x00000243E2BAEB50>: Failed to establish a new connection: [Errno 11001] getaddrinfo failed'))
2023-01-29 09:23:32,706 - instabot version: 0.117.0 (api) - WARNING - HTTPSConnectionPool(host='i.instagram.com', port=443): Max retries exceeded with url: /api/v1/qe/sync/ (Caused by NewConnectionError('<urllib3.connection.HTTPSConnection object at 0x00000243E2BAF550>: Failed to establish a new connection: [Errno 11001] getaddrinfo failed'))
2023-01-29 09:23:32,706 - instabot version: 0.117.0 (api) - WARNING - HTTPSConnectionPool(host='i.instagram.com', port=443): Max retries exceeded with url: /api/v1/launcher/sync/ (Caused by NewConnectionError('<urllib3.connection.HTTPSConnection object at 0x00000243E2BAFC50>: Failed to establish a new connection: [Errno 11001] getaddrinfo failed'))
2023-01-29 09:23:32,706 - instabot version: 0.117.0 (api) - WARNING - HTTPSConnectionPool(host='i.instagram.com', port=443): Max retries exceeded with url: /api/v1/accounts/contact_point_prefill/ (Caused by NewConnectionError('<urllib3.connection.HTTPSConnection object at 0x00000243E2BB4310>: Failed to establish a new connection: [Errno 11001] getaddrinfo failed'))
