2023-01-25 15:38:27,123 - instabot version: 0.117.0 (bot) - INFO - Instabot version: 0.117.0 Started
2023-01-25 15:38:27,125 - instabot version: 0.117.0 (bot) - DEBUG - Bot imported from C:\Users\Rajesh\AppData\Roaming\Python\Python311\site-packages\instabot\bot\bot.py
2023-01-25 15:38:27,126 - instabot version: 0.117.0 (api_login) - INFO - Not yet logged in starting: PRE-LOGIN FLOW!
2023-01-25 15:38:27,135 - instabot version: 0.117.0 (api) - WARNING - HTTPSConnectionPool(host='i.instagram.com', port=443): Max retries exceeded with url: /api/v1/accounts/get_prefill_candidates/ (Caused by NewConnectionError('<urllib3.connection.HTTPSConnection object at 0x0000021A9FE19890>: Failed to establish a new connection: [Errno 11001] getaddrinfo failed'))
2023-01-25 15:38:27,141 - instabot version: 0.117.0 (api) - WARNING - HTTPSConnectionPool(host='i.instagram.com', port=443): Max retries exceeded with url: /api/v1/qe/sync/ (Caused by NewConnectionError('<urllib3.connection.HTTPSConnection object at 0x0000021AA2A36E10>: Failed to establish a new connection: [Errno 11001] getaddrinfo failed'))
2023-01-25 15:38:27,147 - instabot version: 0.117.0 (api) - WARNING - HTTPSConnectionPool(host='i.instagram.com', port=443): Max retries exceeded with url: /api/v1/launcher/sync/ (Caused by NewConnectionError('<urllib3.connection.HTTPSConnection object at 0x0000021AA2A37510>: Failed to establish a new connection: [Errno 11001] getaddrinfo failed'))
2023-01-25 15:38:27,151 - instabot version: 0.117.0 (api) - WARNING - HTTPSConnectionPool(host='i.instagram.com', port=443): Max retries exceeded with url: /api/v1/accounts/contact_point_prefill/ (Caused by NewConnectionError('<urllib3.connection.HTTPSConnection object at 0x0000021AA2A37B90>: Failed to establish a new connection: [Errno 11001] getaddrinfo failed'))
